Workbook

Sheet Start_Here
A1: Chicago + Milwaukee Work Prospecting Expansion
A2: Generated | B2: 46176
A4: Purpose | B4: Expand Adam's hardware / embedded / FPGA / digital-design job board beyond Madison into Chicago and Milwaukee.
A6: Metric | B6: Formula | D6: Read this first
A7: New regional targets | B7: =COUNTA(Regional_Targets!B2:B101) | D7: Best Milwaukee wave | E7: Rockwell Automation, Milwaukee Tool, Generac, Astronautics, GE HealthCare
A8: Chicago targets | B8: =COUNTIF(Regional_Targets!A2:A101,"Chicago") | D8: Best Chicago wave | E8: Motorola Solutions, Northrop Grumman, Molex, Shure, Argonne/Fermilab
A9: Milwaukee targets | B9: =COUNTIF(Regional_Targets!A2:A101,"Milwaukee") | D9: Best pure job-market move | E9: Apply where roles exist, then message engineers with one specific technical hook.
A10: Priority 9+ targets | B10: =COUNTIF(Regional_Targets!I2:I101,">=9") | D10: Best network move | E10: mHUB, Argonne, Fermilab, UW/MSOE/LinkedIn alumni, and company-specific engineers.
A11: Not contacted | B11: =COUNTIF(Regional_Targets!O2:O101,"Not contacted") | D11: Keyword base | E11: embedded, firmware, FPGA, RTL, electrical, validation, test, controls, power electronics.
D12: Rule | E12: Do not wait for perfect fit. Hardware test / validation / controls can be a path into design.
D13: Weekly quota | E13: Apply to 5 real roles + send 8 targeted messages + log every interaction.
D14: Follow-up rule | E14: Follow up seven days after outreach unless the role is closed or they answer.
D15: Reality check | E15: Chicago is broader but logistically harder; Milwaukee is closer and surprisingly aligned.
A18: First 10 companies to hit | B18: Region | C18: Why | D18: Action
A19: Rockwell Automation | B19: Milwaukee | C19: Best controls/industrial automation fit. | D19: Search hardware/firmware/controls and apply.
A20: Milwaukee Tool | B20: Milwaukee | C20: Best embedded/power electronics/motor-control product fit. | D20: Search firmware/electrical/internship/co-op.
A21: Motorola Solutions | B21: Chicago | C21: Best communications + embedded/FPGA Chicago target. | D21: Search Schaumburg FPGA/embedded.
A22: Northrop Grumman | B22: Chicago | C22: Serious RF/electronic warfare hardware. | D22: Search Rolling Meadows engineering.
A23: Generac | B23: Milwaukee | C23: Power systems + embedded controls. | D23: Search firmware/validation/power electronics.
A24: Astronautics | B24: Milwaukee | C24: Avionics + safety-critical embedded systems. | D24: Search avionics software/systems.
A25: Molex | B25: Chicago | C25: Chip-adjacent electronics/interconnect. | D25: Search electrical/validation/signal integrity.
A26: Shure | B26: Chicago | C26: Wireless audio + firmware/RF/DSP. | D26: Search firmware/DSP/RF internships.
A27: GE HealthCare | B27: Milwaukee | C27: Medical imaging systems/software/hardware. | D27: Search Waukesha engineering.

Sheet Research
A1: Outreach tracker
A2: Professor | B2: Lab | C2: Research Area | D2: Date Sent | E2: Follow-up due | F2: Response | G2: Next step | H2: Notes
A3: Parmesh Ramanathan | B3: N/A | C3: General | D3: 46174 | F3: No reply yet | G3: wait for reply | H3: Asked for general info; instant response. Following up is of chief importance. Schedule the meeting.
A4: Daniel Van Der Weide | B4: N/A | C4: General | D4: 5/2/2026, 06/01/2026 | F4: No reply yet | G4: wait for reply | H4: General info, no reply followed up. W, cc follow up from Rob Marshland, should meet up with him for coffee at some point. Met up for coffee, utter chiller. Could do some pcb and embedded work for him and continue my research on the photonic space. Good opportunity, nothin better to do afterall.
A5: Tsung Wei-Huang | B5: n/A | C5: General | D5: 46174 | E5: =IF(D5<>"",D5+7,"") | F5: No reply yet | G5: wait for reply | H5: My advisor; following up on the third email
A6: Julie Hsiao | B6: N/A | C6: General | D6: 46174 | E6: =IF(D6<>"",D6+7,"") | F6: No reply yet | G6: wait for reply | H6: General info, I imagine I'll get a reply.
A7: Georgios Tzimpragoz | B7: N/A | C7: General | D7: 46174 | E7: =IF(D7<>"",D7+7,"") | F7: No reply yet | G7: wait for reply | H7: CompArch; research area unclear.
A8: Joshua San Miguel | B8: N/A | C8: General | D8: 46174 | E8: =IF(D8<>"",D8+7,"") | F8: No reply yet | G8: wait for reply | H8: W guy, just lookin for info.
A9: Azadeh Davoodi | B9: N/A | C9: General | D9: 46174 | E9: =IF(D9<>"",D9+7,"") | F9: No reply yet | G9: wait for reply | H9: Undergraduate studies chair, js lookin for info atm
E10: =IF(D10<>"",D10+7,"") | F10: No reply yet
E11: =IF(D11<>"",D11+7,"") | F11: No reply yet
E12: =IF(D12<>"",D12+7,"") | F12: No reply yet
E13: =IF(D13<>"",D13+7,"") | F13: No reply yet
E14: =IF(D14<>"",D14+7,"") | F14: No reply yet
E15: =IF(D15<>"",D15+7,"") | F15: No reply yet
E16: =IF(D16<>"",D16+7,"") | F16: No reply yet
E17: =IF(D17<>"",D17+7,"") | F17: No reply yet
E18: =IF(D18<>"",D18+7,"") | F18: No reply yet

Sheet Existing_Madison
A1: Company | B1: City / Area | C1: Segment | D1: Why it belongs on your list | E1: Relevant signal for you | F1: Digital-design fit (1-5) | G1: Student access (1-5) | H1: Priority Score | I1: Website | J1: Careers / Contact | K1: Source 1 | L1: Source 2 | M1: First action | N1: Outreach status | O1: Date contacted | P1: Follow-up due
A2: Extreme Engineering Solutions (X-ES) | B2: Verona | C2: FPGA / embedded computing hardware | D2: Local embedded-computing company with FPGA modules, I/O modules, boards, systems, and on-site manufacturing. | E2: Strongest nearby fit if you want FPGA / board-level digital design; explicit student opportunities. | F2: 5 | G2: 5 | H2: 10 | I2: https://www.xes-inc.com/ | J2: https://www.xes-inc.com/about/careers/ | K2: https://www.xes-inc.com/about/ | L2: https://www.xes-inc.com/about/careers/student-co-op-opportunities/ | M2: Apply to any student role, then send a short note asking about hardware / FPGA paths. | N2: N/A, no positions | O2: (7/31/26)
A3: i3 Product Development | B3: Sun Prairie | C3: Product development / embedded / electrical engineering | D3: Nearby engineering firm with in-house electrical engineering, embedded software, prototyping, and internships. | E3: Great practical fit if you want to talk to real product-development engineers and get hardware exposure fast. | F3: 4 | G3: 5 | H3: 9 | I3: https://i3pd.com/ | J3: https://i3pd.com/jobs/ | K3: https://i3pd.com/contact-us/ | L3: https://i3pd.com/team/ | M3: Apply to internships or entry paths and mention your interest in embedded / digital hardware projects. | N3: No positions, but still sent a resume and cover letter. | O3: (7/31/26)
A4: SixLine Semiconductor | B4: Middleton | C4: Pure-play semiconductor startup | D4: Commercializing carbon-nanotube semiconductor technology for next-generation devices. | E4: Best local pure-play semiconductor networking target; founder/startup conversations could be valuable even if openings are sparse. | F4: 4 | G4: 5 | H4: 9 | I4: https://www.sixlinesemi.com/ | J4: https://www.sixlinesemi.com/contact | K4: https://www.sixlinesemi.com/ | L4: https://wedc.org/innovate-in-wisconsin/innovation-investment-portfolio/sixline-semiconductor-inc/ | M4: Send founder/team outreach asking for a 15-minute learning conversation about local semiconductor paths. | N4: No positions, though I did submit a google form so ill be on the look out for responses to that. | O4: (7/31/26)
A5: Sound Devices | B5: Madison / Reedsburg | C5: Professional audio / embedded hardware | D5: Designs, assembles, and supports pro-audio and wireless products in Wisconsin; Madison office has embedded roles. | E5: Very solid embedded-hardware target with real products, local engineering, and a history of internships. | F5: 4 | G5: 4 | H5: 8 | I5: https://www.sounddevices.com/ | J5: https://www.sounddevices.com/company/careers/ | K5: https://www.sounddevices.com/company/careers/ | L5: https://www.sounddevices.com/embedded-software-engineer-madison-wi/ | M5: Reach out to engineering recruiting or apply directly to embedded openings; mention hardware + real-time interest. | N5: Not contacted
A6: Sub-Zero Group | B6: Fitchburg / Madison | C6: Product engineering / controls / appliance electronics | D6: Large local product company with manufacturing and engineering in Fitchburg plus student programs. | E6: Not semiconductor, but a real Wisconsin hardware employer with product-development and controls/electronics paths. | F6: 3 | G6: 5 | H6: 8 | I6: https://www.subzero-wolf.com/ | J6: https://www.subzero-wolf.com/about/careers | K6: https://www.subzero-wolf.com/about/careers/locations | L6: https://www.subzero-wolf.com/about/careers/co-op-program | M6: Watch student and engineering openings; tailor outreach to product development, controls, or electronics. | N6: Not contacted
A7: Johnson Health Tech | B7: Cottage Grove | C7: Connected products / electronics / embedded systems | D7: Cottage Grove engineering team has posted senior electrical and embedded software roles for connected products. | E7: Good nearby product-electronics company if you want analog/digital hardware, system connectivity, and firmware-adjacent work. | F7: 4 | G7: 3 | H7: 7 | I7: https://www.johnsonhealthtech.com/ | J7: https://www.johnsonhealthtech.com/us/eng/careers | K7: https://www.johnsonhealthtech.com/us/eng/careers | L7: https://recruiting.paylocity.com/recruiting/jobs/List/2034/Johnson-Heath-Tech-Companies | M7: Check the Cottage Grove postings and send a concise note about hardware / embedded interest. | N7: No Positions. | O7: (7/31/26)
A8: Promega | B8: Madison | C8: Scientific instruments / benchtop systems | D8: Madison-headquartered manufacturer that develops reagents and instruments, with engineering and instrument-service roles. | E8: Useful if you want to enter hardware through scientific instruments, system integration, service, or manufacturing engineering. | F8: 3 | G8: 4 | H8: 7 | I8: https://www.promega.com/ | J8: https://www.promega.com/aboutus/careers/ | K8: https://www.promega.com/aboutus/company-information/ | L8: https://www.promega.com/aboutus/press-releases/global/2022/may-17-2022-forensic-laboratories-flexibility-with-spectrum-ce/ | M8: Look for instrument, service, hardware, or manufacturing-engineering roles on the Madison campus. | N8: Not contacted
A9: Springs Window Fashions | B9: Middleton | C9: Connected products / firmware / controls | D9: Middleton team is hiring firmware and electrical engineers for motorized and connected products, plus internships. | E9: Not semiconductor, but a very real nearby embedded-products employer. | F9: 3 | G9: 4 | H9: 7 | I9: https://springswindowfashions.com/ | J9: https://springswindowfashions.com/careers/career-opportunities/ | K9: https://springswindowfashions.com/careers/career-opportunities/ | L9: https://careers-springswindowfashions.icims.com/jobs/12354/firmware-engineer/job | M9: Track firmware/electrical roles and mention interest in controls, connected devices, and embedded systems. | N9: Not contacted
A10: Qolab | B10: Madison | C10: Quantum hardware / semiconductor-compatible fabrication | D10: Madison lab building superconducting quantum hardware with advanced semiconductor-compatible fabrication. | E10: Good advanced-hardware startup target for conversations about control, packaging, readout, and scalable hardware systems. | F10: 4 | G10: 3 | H10: 7 | I10: https://qolab.ai/ | J10: https://qolab.ai/contact-us/ | K10: https://qolab.ai/ | L10: https://qolab.ai/contact-us/ | M10: Send a concise hardware-interest note and watch for lab or hardware-engineering openings. | N10: Not contacted
A11: CAMECA Instruments (Atom Probe Technology Center) | B11: Fitchburg / Madison | C11: Semiconductor metrology / instrumentation | D11: Madison-area site develops and manufactures LEAP atom probe tools used in materials and semiconductor work. | E11: Relevant if you can enter through electronics, test, instrumentation, or manufacturing-engineering-adjacent work. | F11: 3 | G11: 3 | H11: 6 | I11: https://www.cameca.com/ | J11: https://www.cameca.com/company/careers | K11: https://www.cameca.com/contact/production-sites/atom-probe-technology-center | L11: https://www.cameca.com/company/careers | M11: Check Madison-site openings and look for electronics, instrument, test, or manufacturing roles. | N11: Not contacted
A12: Infleqtion | B12: Madison | C12: Quantum hardware / sensing | D12: Quantum technology company with a Madison office spanning hardware, sensing, and software. | E12: Less direct than X-ES, but still worth tracking for hardware / experimental systems opportunities. | F12: 3 | G12: 3 | H12: 6 | I12: https://infleqtion.com/ | J12: https://infleqtion.com/careers/ | K12: https://infleqtion.com/careers/ | L12: https://infleqtion.com/infleqtion-and-university-of-colorado-boulder-collaborate/ | M12: Track openings and send a short Madison-office note if you see a hardware-adjacent fit. | N12: Not contacted
A13: Thermo Fisher Scientific | B13: Madison | C13: Analytical instrumentation / service / software | D13: Madison remains a real Thermo Fisher instrument site, with local service/support and instrument/software activity. | E13: Not your purest digital-design fit, but worth watching for hardware-support, instrumentation, automation, or local software roles. | F13: 3 | G13: 3 | H13: 6 | I13: https://www.thermofisher.com/us/en/home.html | J13: https://jobs.thermofisher.com/ | K13: https://www.thermofisher.com/us/en/home/technical-resources/manufacturing-site-iso-certifications.html | L13: https://jobs.thermofisher.com/global/en/job/R-01346167/Software-Development-Manager | M13: Search Madison openings with keywords like instrument, hardware, automation, validation, software, and service. | N13: No positions, I'll check back. | O13: (7/31/26)
A14: SHINE Technologies | B14: Janesville / Fitchburg | C14: Fusion systems / advanced hardware | D14: Builds fusion-related systems in southern Wisconsin and is hiring in Janesville and Fitchburg. | E14: Worth including if you want hard-tech exposure, engineering rigor, and local advanced-energy hardware contacts. | F14: 3 | G14: 3 | H14: 6 | I14: https://www.shinefusion.com/ | J14: https://www.shinefusion.com/about/careers | K14: https://www.shinefusion.com/about/careers | L14: https://www.shinefusion.com/videos/shine-technologies-systems-and-manufacturing-facility-in-fitchburg-wisconsin | M14: Track systems, manufacturing, controls, or hardware roles and send a targeted note about advanced hardware interest. | N14: Not contacted
A15: NorthStar Medical Radioisotopes | B15: Beloit | C15: Accelerator-based systems / automation / advanced hardware | D15: Beloit campus uses electron beam accelerators and is hiring engineering roles including automation. | E15: Interesting if you want complex systems, controls, automation, or accelerator-adjacent hardware exposure. | F15: 3 | G15: 3 | H15: 6 | I15: https://www.northstarnm.com/ | J15: https://www.northstarnm.com/careers/ | K15: https://www.northstarnm.com/careers/ | L15: https://www.northstarnm.com/company/facilities/ | M15: Look for automation, controls, electrical, or systems roles and send a short learning-oriented outreach note. | N15: Not contacted
A16: ABS Global / Genus | B16: Windsor / DeForest | C16: Biosystems / embedded hardware | D16: Nearby biosystems team has recently posted embedded software work in Windsor, giving you another local embedded-systems angle. | E16: Not semiconductor, but worth one shot because it is close and has shown embedded hiring. | F16: 3 | G16: 3 | H16: 6 | I16: https://www.absglobal.com/abs-careers/ | J16: https://www.absglobal.com/abs-careers/ | K16: https://www.absglobal.com/abs-careers/ | L16: https://www.ziprecruiter.com/c/Genus-PLC/Job/Sr-Software-Engineer%2C-Embedded/-in-Windsor%2CWI?jid=7424564879546158 | M16: Search Windsor / DeForest engineering postings and send one concise embedded-systems outreach note. | N16: Not contacted
A17: Type One Energy | B17: Madison | C17: Fusion hardware / controls / advanced energy | D17: Madison office in a venture-backed fusion company with local presence and technical roles. | E17: Longer-shot for digital design, but still worth keeping on the board for serious hard-tech networking. | F17: 3 | G17: 2 | H17: 5 | I17: https://typeoneenergy.com/home/ | J17: https://typeoneenergy.com/careers/ | K17: https://typeoneenergy.com/careers/ | L17: https://typeoneenergy.teamtailor.com/jobs | M17: Track Madison openings and keep this as a network target rather than a primary first outreach wave. | N17: Not contacted
A18: Epic Technologies | B18: Verona | C18: Medical Software | D18: Damn near highest market cap outta wisconsin | E18: Goated software company, shipping things that matter, I imagine immense equity deals as well | F18: 2 | G18: 2 | H18: 10 | N18: Applied for 2027 summer internship | O18: (09/21/26)
A19: Alphabet Inc | B19: US | C19: errything | N19: Applied for research internship off of handshake | O19: (7/31/26)
A20: America Family Insurance | B20: Madison | C20: Insurance services | N20: 08/05/25 No positions
A21: QBE | B21: Madison | C21: Insurance services | D21: Machine learning and data science aspect | E21: type shi | N21: (09/21/26) | P21: GOT A PHONE INTERVIEW NICE
A22: plexus | B22: Madison | C22: data and communications products | D22: software and shi idk | N22: (09/21/26)
A23: Ambarella | B23: international | C23: semiconductor and computer vision | D23: engineering shi | N23: (09/21/26)
A24: IBM | B24: international | C24: silicon researcher | N24: (09/21/26)
A25: Motorola | B25: international | C25: FPGA design intern | N25: (09/21/26)
A26: Tesla | B26: international | C26: AI HARDWARD INTERN | N26: 46293
A27: Dell | B27: Texas | C27: Cloud service gateway hardware intern | D27: Hardware and shi | E27: Hardware projects and curiousity? | N27: 46293
A28: Micron | B28: Texas | C28: Intern design engineer | N28: 46293
A29: NXP semis | B29: Texas | C29: Digital Design Intern | N29: 46293
A30: GE-healthcare | B30: MADISON | C30: Digital Design Intern | N30: 46293
N31: 46293

Sheet MuseSearch
A1: Date | B1: Company | C1: Role | D1: Location | E1: Posting URL | F1: Status | G1: Resume | H1: Confirmation | I1: Notes
A2: 2026-10-18 | B2: Meta | C2: ASIC Design Engineer Intern | D2: Sunnyvale, CA | E2: https://www.metacareers.com/jobs/1406976394946562 | F2: SUBMITTED | G2: asResumeFa26_i.pdf | H2: "Thanks for applying, Adam Shebani." / "Your application for the ASIC Design Engineer Intern role has been received." | I2: Agent end-to-end test (authorized). No confirmation number; no Career Profile account created.
A3: 2026-10-19 | B3: Meta | C3: ASIC Engineering Intern, Design Verification (Silicon Engineering) | D3: Sunnyvale, CA | E3: https://www.metacareers.com/jobs/1079763448023260 | F3: SUBMITTED | G3: asResumeFa26_i.pdf | H3: "Thanks for applying, Adam Shebani. Your application for the ASIC Engineering Intern, Design Verification (Silicon Engineering) role has been received." | I3: Prelim AI screener could not verify 2 min quals from resume — "Submit anyway" clicked (preliminary only).
A4: 2026-10-19 | B4: Tenstorrent | C4: Physical Design & DFT Intern | D4: Austin TX / Santa Clara CA / Boston MA / Fort Collins CO | E4: https://job-boards.greenhouse.io/tenstorrentuniversity/jobs/5256706007 | F4: SUBMITTED | G4: asResumeFa26_i.pdf + transcript asSum26Transcript.pdf | H4: "Thank you for applying. Your application has been received." | I4: reCAPTCHA blocked 5 auto attempts; submit succeeded on retry. Teams: Physical Design + Advanced Physical Design.
A5: 2026-10-19 | B5: GlobalFoundries | C5: Foundation IP Design Verification Intern (Summer 2027) | D5: Santa Clara, CA | E5: https://globalfoundries.wd1.myworkdayjobs.com/en-US/External/job/USA---California---Santa-Clara/Foundation-IP-Design-Verification-Intern--Summer-2027-_JR-2604356/apply/applyManually | F5: SUBMITTED | G5: asResumeFa26_i.pdf | H5: "Application Submitted — Your application has successfully been submitted. You have no more tasks." | I5: Workday account created w/ burner Gmail. 6 background Qs answered by Adam, now in DB.
A6: 2026-10-19 | B6: HPE | C6: ASIC Verification Engineering Intern | D6: Roseville, CA 95747 (Hybrid) | E6: https://careers.hpe.com (Job ID 1214219) | F6: SUBMITTED | G6: asResumeFa26_i.pdf | H6: "Adam, you have successfully applied for: ASIC Verification Engineering Intern, Roseville, California, 95747" | I6: Phenom platform (no account needed). Candidate ID CANDIDATE-3-6146137. 6 compliance Qs answered by Adam, now in DB.
A7: 2026-10-19 | B7: HPE | C7: ASIC Intern | D7: Sunnyvale, CA 94089 | E7: https://careers.hpe.com (Job ID 1214034) | F7: SUBMITTED | G7: asResumeFa26_i.pdf | H7: "Thank you for your Application — ASIC Intern, Sunnyvale, California, 94089" | I7: Phenom platform (no account needed). Same 6 compliance answers.
A8: 2026-10-19 | B8: Amazon | C8: Hardware Development Engineer Intern (Summer 2027) | D8: Sunnyvale CA / North Reading MA / Hawthorne CA | E8: https://amazon.jobs/en/jobs/10578090/hardware-development-engineer-intern-summer-2027 | F8: SUBMITTED | G8: asResumeFa26_i.pdf | H8: "Thank you for applying! Your application for Hardware Development Engineer Intern, Summer 2027 (Job ID: 10578090) has been submitted." | I8: amazon.jobs account created w/ burner Gmail. 10 job-specific + blue-badge answers from Adam, now in DB. Hardware areas: form had no RTL/PCB option, selected Other.
A9: 2026-10-20 | B9: Meta | C9: ASIC Engineer Intern - Architecture | D9: Austin TX / Sunnyvale CA | E9: https://www.metacareers.com/jobs/1096213456288397 | F9: SUBMITTED | G9: asResumeFa26_i.pdf | H9: "Thanks for applying, Adam Shebani" — Meta confirmation email 2026-10-20 | I9: Submitted by 10-20 loop run (env blocker healed). Prelim AI flagged 2 quals, submitted anyway. No Career Profile created.
A10: 2026-10-20 | B10: Meta | C10: Hardware Engineer Intern - Camera & Sensing Architecture | D10: Redmond WA / Sunnyvale CA | E10: https://www.metacareers.com/jobs/29216393121298039 | F10: SUBMITTED | G10: asResumeFa26_i.pdf | H10: "Thanks for applying, Adam Shebani" — Meta confirmation email 2026-10-20 | I10: Submitted by 10-20 loop run (env blocker healed). Prelim AI flagged 4 quals, submitted anyway. Guest apply.
A11: 2026-10-19 | B11: Cirrus Logic | C11: Digital Design Engineer Intern | D11: Austin, TX | E11: https://jobs.eu.lever.co/cirrus/0310fbd1-a2a8-4c0f-a842-86e05ae7d98e/apply | F11: BLOCKED | G11: asResumeFa26_i.pdf | I11: Env: 1Password autofill withholding page views. Retry when healed.
A12: 2026-10-20 | B12: Astera Labs | C12: Design Verification Engineer Intern | D12: San Jose, CA | E12: https://job-boards.greenhouse.io/asteraearlycareer2027/jobs/4722012005 | F12: SUBMITTED | G12: asResumeFa26_i.pdf | H12: Greenhouse: "Thank you for applying to Astera Labs Early Career - North America 2027" (2026-10-20) | I12: Submitted by 10-20 loop run (env blocker healed).
A13: 2026-10-20 | B13: Astera Labs | C13: Digital Design Intern | D13: San Jose, CA | E13: https://job-boards.greenhouse.io/asteraearlycareer2027/jobs/4731407005 | F13: SUBMITTED | G13: asResumeFa26_i.pdf | H13: Greenhouse: "Thank you for applying to Astera Labs Early Career - North America 2027" (2026-10-20) | I13: Submitted by 10-20 loop run (env blocker healed).
A14: 2026-10-19 | B14: Meter | C14: Hardware Engineer Intern | D14: Remote (US) | E14: https://jobs.ashbyhq.com/meter/a5f1e4c3-2930-4933-ab38-8f600486494b/application?embed=true | F14: DEAD POSTING | I14: Ashby "Job not found" — role removed.
A15: 2026-10-20 | B15: Tenstorrent | C15: Hardware Intern - Architecture, AI HW & SoC (USA) | D15: Austin TX / Boston MA / Fort Collins CO / Santa Clara CA | E15: https://job-boards.greenhouse.io/tenstorrentuniversity/jobs/5256691007 | F15: SUBMITTED | G15: asResumeFa26_i.pdf + transcript | H15: "Thank you for applying. Your application has been received. If there is a fit, someone will be getting back to you." | I15: First-attempt submit worked; team-preference dropdown left blank (Adam open broadly).
A16: 2026-10-20 | B16: Amazon | C16: Hardware Development Engineer Intern/Co-Op, ROBOTICS - 2027 | D16: North Reading / Westboro MA | E16: https://amazon.jobs/en/jobs/10535282 | F16: SUBMITTED | G16: asResumeFa26_i.pdf | H16: "Thank you for applying! Your application for Hardware Development Engineer Intern/Co-Op, ROBOTICS - 2027 (Job ID: 10535282) has been submitted." | I16: Answers from Adam 10-20: CAD none-of-listed (Altium/KiCad), grad 12/20/2027, robotics minimal.
A17: 2026-10-20 | B17: Hudson River Trading | C17: Hardware Design Engineer - 2027 Grads | D17: New York, NY | E17: https://www.hudsonrivertrading.com/hrt-job/hardware-design-engineer-2027-grads/ | F17: SUBMITTED | G17: asResumeFa26_n.pdf | H17: "Your application has been received! If you are selected to continue the interview process, you will receive an email detailing what's next." | I17: One-application policy honored (Hardware Design Engineer). Employer dropdown: Adam chose "Other - No Former Employment". EEO race: no Two-or-More option, selected "I don't wish to answer".
A18: 2026-10-20 | B18: Micron | C18: Intern - SSD Hardware Engineering (JR114232) | D18: Longmont, CO | E18: https://careers.micron.com | F18: SUBMITTED | G18: asResumeFa26_i.pdf | H18: "Thank you for your application, Adam!" — Micron success page 2026-10-20 | I18: Adam answers 10-20: applied before Yes, terminated No, board No/No. Availability: more than 2 months after offer (earliest start 05/14/2027).
A19: 2026-10-20 | B19: RTX | C19: Digital Hardware Design Engineer (2027 NCG) | D19: El Segundo, CA | E19: https://careers.rtx.com/global/en/job/01873795/Digital-Hardware-Design-Engineer-Onsite | F19: SUBMITTED | G19: asResumeFa26_n.pdf | H19: Job App ID 751faeb486469001209fd0603c020002; Candidate C13046056 | I19: Adam waived clearance knockout; clearance answered truthfully No (never held)
A20: 2026-10-21 | B20: Skydio | C20: Wireless Hardware Engineer Intern - Summer 2027 | D20: San Mateo, CA | E20: https://jobs.ashbyhq.com/skydio/1ac972b1-8094-4765-8869-63e1c4d50dea/application?embed=true | F20: SUBMITTED | G20: asResumeFa26_i.pdf | H20: "Success — Thank you for submitting your application. We are thrilled you would consider joining us. The team will review your application, and we will be in touch soon if it seems like there could be a good fit." (Ashby, no confirmation number) | I20: No account required; start month May 2027 selected; gov-employment No; transcript not required.
A21: 2026-10-21 | B21: onsemi | C21: Semiconductor AI Specialist Intern (Spring 2027, job 2506918) | D21: Gresham, OR | E21: https://hctz.fa.us2.oraclecloud.com/hcmUI/CandidateExperience/en/sites/CX_1001/job/2506918 | F21: SUBMITTED | G21: asResumeFa26_i.pdf | H21: Candidate profile: ACTIVE JOB APPLICATIONS — Status: Under Consideration, Job ID 2506918, Applied on 10/21/2026 | I21: How-heard Company Website -> industry interest (DB). Email verification completed. No password account; profile under adamsheb414@gmail.com. Transcript not required.
A22: 2026-10-21 | B22: Rockwell Automation | C22: Intern - Hardware Development Engineer (May-Aug 2027, req R26-6892) | D22: Mayfield Heights, OH | E22: https://rockwellautomation.wd1.myworkdayjobs.com/external_rockwell_automation/job/Mayfield-Heights-Ohio-United-States/Intern--Hardware-Development-Engineer--May---Aug-2027-_R26-6892-1 | F22: SUBMITTED | G22: asResumeFa26_i.pdf | H22: "Application Submitted — Thank you for applying to Rockwell Automation! ... We've received your application, and someone from our team will be in touch soon." | I22: Candidate Home: Active (1), Under Review, Date Submitted 10/21/2026. Workday account created (musebabashebani@gmail.com). Transcript not required.
A23: 2026-10-21 | B23: Extreme Engineering Solutions (X-ES) | C23: Hardware Debug Engineer (req #HARDW001758, new-grad) | D23: Verona, WI | E23: https://www.xes-inc.com/about/careers/full-time-employment-opportunities/hardware-debug-engineer/ | F23: SUBMITTED | G23: asResumeFa26_n.pdf | H23: "You applied for Hardware Debug Engineer — Thank you! Your application was submitted." Application ID 04ff826e-a0e2-4ef1-bf89-5cb22d7c0830 | I23: UKG/UltiPro candidate account created (musebabashebani@gmail.com). All questions DB-covered. Transcript not required.
A24: 2026-10-21 | B24: Extreme Engineering Solutions (X-ES) | C24: Test Engineering Co-Op (Summer/Fall 2027, May-Dec 2027) | D24: Verona, WI | E24: https://www.xes-inc.com/about/careers/student-co-op-opportunities/test-engineering-co-op/ | F24: SUBMITTED | G24: asResumeFa26_i.pdf | H24: "You applied for Test Engineering Co-Op. Thank you! Your application was submitted." Application ID df307081-9a8d-415c-bb1f-858535c56ce7 | I24: UKG/UltiPro candidate account created (musebabashebani@gmail.com). Term Summer/Fall 2027, start 05/14/2027. Transcript not required.
A25: 2026-10-21 | B25: Johnson Health Tech | C25: Embedded Software Engineer-Innovation Team (new-grad, full-time) | D25: Cottage Grove, WI | E25: https://recruiting.paylocity.com/Recruiting/Jobs/Details/4176830 | F25: SUBMITTED | G25: asResumeFa26_n.pdf | H25: "Your application has been received! Thank you for applying." (Paylocity, no confirmation number) | I25: Salary 58000 yearly. SMS consent Yes. No account required. Transcript not required. Cover letter skipped (optional).
A26: 2026-10-21 | B26: Dell Technologies | C26: Hardware Engineer 1 Intern (job 298141) | D26: Austin, TX | E26: https://iawmqy.fa.ocs.oraclecloud.com/hcmUI/CandidateExperience/en/sites/careers/job/298141 | F26: SUBMITTED | G26: asResumeFa26_i.pdf | H26: Confirmation: "Thank you for your job application." Status: Under Consideration, Applied on 10/21/2026 (Oracle job 298141) | I26: Identity-verification email code (10-min validity) expired twice while the user-approval card sat unapproved — no user present on detached run. Email entered, terms accepted; form not reached. RETRY when Adam can approve the code card.
... A29: 2026-10-21 | B29: Garmin | C29: FPGA Engineer Intern (Req 19836) | D29: Olathe, KS | E29: https://careers.garmin.com/jobs/19836?icims=1 | F29: SUBMITTED | G29: asResumeFa26_i.pdf | H29: Confirmation: "Your application was submitted successfully. Thank you for applying." / "You are currently submitted to this job." (iCIMS Req 19836) | I29: iCIMS Step 1 blocked on Professional Experience block: City, Title, Start Date, Reason for Leaving, Country, State for Badger Moving (DB has employer + end 10/2025 only). ZIP resolved 53716. Burner email verified; resume attached; no login created yet.
A30: 2026-10-21 | B30: Extreme Engineering Solutions (X-ES) | C30: Embedded Hardware Engineering Co-Op (req ASSOC001741, Summer/Fall 2027) | D30: Verona, WI | E30: https://www.xes-inc.com/about/careers/student-co-op-opportunities/embedded-hardware-engineering-co-op/ | F30: PENDING | G30: asResumeFa26_i.pdf | I30: X-ES requires a Candidate Questionnaire PDF with the application; its questions (relevant coursework, 0-5 skill ratings, 0-2 team interest ratings) escalated to Adam. No account created, nothing submitted.
A31: 2026-10-21 | B31: Extreme Engineering Solutions (X-ES) | C31: Embedded Software Engineering Co-Op (req ASSOC001742, Summer/Fall 2027) | D31: Verona, WI | E31: https://www.xes-inc.com/about/careers/student-co-op-opportunities/embedded-software-engineering-co-op/ | F31: BLOCKED | G31: asResumeFa26_i.pdf | I31: UKG/UltiPro portal requires sign-in; account musebabashebani@gmail.com exists (created by earlier X-ES application) but no saved login in this window and password is never stored; password reset not authorized on detached run. Likely also needs candidate questionnaire.
A32: 2026-10-21 | B32: Nokia | C32: Hardware Development Co-Op (Job 40268) | D32: Murray Hill, NJ (live posting, not Remote US) | E32: https://fa-evmr-saasfaprod1.fa.ocs.oraclecloud.com/hcmUI/CandidateExperience/en/sites/CX_1/job/40268 | F32: SKIPPED | I32: Co-op term Jan–Aug 2027 starts before approved earliest start 05/14/2027 (approved terms Summer/Fall only). Novel questions escalated: part-time work, flexible schedule, how-heard fixed options.
A33: 2026-10-21 | B33: Sub-Zero Group | C33: 2027 Engineering Co-op (req 2026E007282) | D33: Madison, WI | E33: https://recruiting2.ultipro.com/SUB1000SUBZ/JobBoard/ffaa667e-61b4-4b38-b427-2cb6982a41a3/OpportunityDetail?opportunityId=7c3b1a75-6342-4c54-b0b9-dad278ec2df9 | F33: SKIPPED | I33: Posting fixes co-op to Spring term Jan–Aug 2027, before approved earliest start 05/14/2027. No Summer/Fall term offered.
A34: 2026-10-21 | B34: Microsoft | C34: Hardware Engineering Internship (6-Month Program, job 200057051) | D34: Redmond, WA | E34: https://apply.careers.microsoft.com/careers/job/1970393557002608 | F34: DEAD | I34: Page shows "No longer accepting applications" banner; no Apply button. Role closed.
A35: 2026-10-21 | B35: Rockwell Automation | C35: Intern - Embedded Controls Engineering (R26-5043-2) | D35: Orlando, FL | E35: https://rockwellautomation.wd1.myworkdayjobs.com/external_rockwell_automation/job/Orlando-Florida-United-States/Intern---Embedded-Controls-Engineering_R26-5043-2 | F35: DEAD | I35: Workday returns "page doesn't exist"; title/req searches found no equivalent posting. Role closed/filled.
A36: 2026-10-21 | B36: Amazon.com Services LLC | C36: Hardware Development Engineer Intern (Winter 2027, job 10584121) | D36: Remote (US) | E36: https://www.amazon.jobs/en/jobs/10584121/hardware-development-engineer-intern-winter-2027 | F36: SKIPPED | I36: Posting is Winter 2027 term; approved terms are Summer/Fall only (earliest start 05/14/2027).
A37: 2026-10-21 | B37: Meta | C37: ASIC Engineer Intern - Design Verification - Silicon Engineering | D37: Sunnyvale, CA | E37: https://www.metacareers.com/jobs/1079763448023260 | F37: SKIPPED | I37: Duplicate — already submitted 2026-10-19 (same job ID). Not re-applied.
A38: 2026-10-21 | B38: Sound Devices | C38: Embedded Software Engineer (new-grad) | D38: Madison, WI | E38: https://www.sounddevices.com/embedded-software-engineer-madison-wi/ | F38: NO_OPENING | I38: Posting is contact-email only (careers@sounddevices.com) — no application form. Per loop rule, never email.
A39: 2026-10-21 | B39: SixLine Semiconductor | C39: (no postings — contact form only) | D39: Middleton, WI | E39: https://www.sixlinesemi.com/contact | F39: NO_OPENING | I39: Careers page is a contact form only; Adam already submitted their Google form 7/31/26.
A40: 2026-10-21 | B40: Extreme Engineering Solutions (X-ES) | C40: Hardware Test Engineer (new-grad) | D40: Verona, WI | E40: https://www.xes-inc.com/about/careers/full-time-employment-opportunities/hardware-test-engineer/ | F40: SKIPPED | I40: Posting explicitly open to December 2026 graduates; Adam graduates Dec 2027.
A41: 2026-10-22 | B41: Skydio | C41: Hardware Test and Reliability Intern (Summer 2027) | D41: San Mateo, CA | E41: https://jobs.ashbyhq.com/skydio/36d75e36-eeb2-4399-8887-37c4a5ff5800/application?embed=true | F41: SUBMITTED | G41: asResumeFa26_i.pdf | H41: Success banner, fields disabled (Ashby, no conf number) | I41: Cover letter generated but no upload slot on form (resume-only); no essay field
A42: 2026-10-22 | B42: Astera Labs | C42: Applied AI Engineer Intern, Silicon Engineering (Summer 2027) | D42: San Jose, CA | E42: https://job-boards.greenhouse.io/asteraearlycareer2027/jobs/4727602005 | F42: SUBMITTED | G42: asResumeFa26_i.pdf | H42: Greenhouse confirmation page | I42: Cover letter generated but no upload slot on form; not attached
...

Sheet Regional_Targets
A1: Region | B1: Company | C1: City / Area | D1: Segment | E1: Why it belongs on your list | F1: Relevant signal for you | G1: Digital-design fit (1-5) | H1: Student access (1-5) | I1: Priority Score | J1: Website | K1: Careers / Contact | L1: Source 1 | M1: Source 2 | N1: First action | O1: Outreach status | P1: Date contacted | Q1: RESPONSE | R1: Role keywords to search | S1: Contact target | T1: Notes | U1: Column1
A2: Chicago | B2: Motorola Solutions | C2: Chicago / Schaumburg, IL | D2: Public safety communications / embedded / RF / cybersecurity | E2: Large Chicago-area hardware/software employer with radios, secure embedded systems, communications infrastructure, and an official careers funnel. | F2: Strong fit for embedded C/C++, FPGA/RTL, RF-adjacent systems, verification, and security-minded low-level work. | G2: 5 | H2: 4 | I2: =G2+H2 | J2: https://www.motorolasolutions.com/ | K2: https://www.motorolasolutions.com/en_us/about/careers.html | L2: https://www.motorolasolutions.com/en_us/about/careers.html | M2: https://motorolasolutions.wd5.myworkdayjobs.com/en-US/Careers | N2: Search Schaumburg for FPGA, embedded, test, firmware, cyber embedded; apply first, then message a UW alum/engineer. | O2: come back in september | P2: 46253 | R2: FPGA, embedded software, firmware, cyber embedded, C/C++, RF, verification | S2: Engineer or recruiter in Schaumburg embedded/FPGA org | T2: Top Chicago-area digital-hardware target.
A3: Chicago | B3: Northrop Grumman | C3: Rolling Meadows, IL | D3: Defense electronics / RF / electronic warfare / embedded systems | E3: Rolling Meadows is a major engineering site for navigation, targeting, and self-protection systems. | F3: Very strong technical match for RF systems, embedded, FPGA/RTL, verification, systems test, and hardware bring-up. | G3: 5 | H3: 3 | I3: =G3+H3 | J3: https://www.northropgrumman.com/ | K3: https://jobs.northropgrumman.com/ | L3: https://www.northropgrumman.com/careers/northrop-grumman-in-rolling-meadows-illinois | M3: https://jobs.northropgrumman.com/locations/rolling-meadows-il/jobs/ | N3: Search Rolling Meadows openings; be realistic about clearance requirements, but do not self-reject. | O3: Not contacted | P3: 46239 | R3: FPGA, RF systems, embedded software, electronic warfare, test engineer, verification | S3: Early-career recruiter or RF/embedded engineer | T3: Great signal if you want serious defense electronics. APPLIED!
A4: Chicago | B4: Molex | C4: Lisle, IL | D4: Electronics connectivity / interconnect / data center / industrial automation | E4: Global electronics leader headquartered in the Chicago suburbs with exposure to automotive, data center, industrial automation, 5G, cloud, healthcare, and consumer devices. | F4: Good chip-adjacent path if you want high-speed hardware, connectors, optics, validation, signal integrity, and manufacturing-scale engineering. | G4: 4 | H4: 4 | I4: =G4+H4 | J4: https://www.molex.com/ | K4: https://www.molex.com/en-us/about/careers | L4: https://www.molex.com/en-us/about/careers | M4: https://www.molex.com/en-us/about | N4: Search Lisle for electrical, signal integrity, validation, test, product development, and manufacturing engineering. | O4: Not contacted | P4: 46239 | R4: electrical engineer, signal integrity, validation, test, product development, optics | S4: Engineer/recruiter in Lisle electronics group | T4: Very practical hardware employer.
A5: Chicago | B5: Shure | C5: Niles, IL | D5: Audio electronics / wireless / embedded / firmware | E5: Niles-based audio electronics company with careers and internship programs; products include wireless systems and collaboration/audio technology. | F5: Good fit for embedded firmware, digital audio, RF/wireless, signal processing, test, and hardware-software product work. | G5: 4 | H5: 4 | I5: =G5+H5 | J5: https://www.shure.com/ | K5: https://www.shure.com/en-us/careers | L5: https://www.shure.com/en-us/careers | M5: https://www.shure.com/en-us/careers/internships | N5: Search internships/open roles for firmware, embedded, DSP, RF, electrical, test; tailor outreach to audio + signal systems. | O5: No internship opportunities | P5: 46255 | R5: firmware, embedded, DSP, RF, wireless, electrical engineer, test | S5: Firmware/electrical engineer or university recruiter | T5: More product-electronics than semiconductor, but high quality.
A6: Chicago | B6: Zebra Technologies | C6: Lincolnshire, IL | D6: Enterprise hardware / mobile computing / barcode/RFID / intelligent operations | E6: Chicago-area hardware/software company with intelligent operations products across retail, healthcare, manufacturing, logistics, and field operations. | F6: Useful for embedded devices, mobile hardware, RFID/scanning, Android/Linux systems, firmware, test, and hardware/software integration. | G6: 4 | H6: 3 | I6: =G6+H6 | J6: https://www.zebra.com/us/en.html | K6: https://www.zebra.com/us/en/about-zebra/careers.html | L6: https://www.zebra.com/us/en/about-zebra/careers.html | M6: https://careers.zebra.com/careers?domain=zebra.com&query=%2A | N6: Search Lincolnshire for firmware, embedded, hardware test, Linux, mobile computing, RFID/scanner roles. | O6: Not contacted | R6: embedded, firmware, Linux, Android, RFID, barcode, hardware test | S6: Embedded/hardware engineer or product recruiter | T6: Good hardware-software systems company.
A7: Chicago | B7: S&C Electric Company | C7: Chicago, IL | D7: Power grid hardware / controls / firmware / automation | E7: Chicago-based grid equipment company with official careers page and engineering/product roles. | F7: Relevant if you want controls, power electronics, protection systems, firmware, FPGA-adjacent industrial electronics, and fieldable hardware. | G7: 4 | H7: 3 | I7: =G7+H7 | J7: https://www.sandc.com/ | K7: https://www.sandc.com/en/careers/ | L7: https://www.sandc.com/en/careers/ | M7: https://www.sandc.com/ | N7: Search firmware, controls, electrical designer, protection systems, power electronics; message engineers in automation or product development. | O7: Not contacted | R7: firmware, controls, power electronics, electrical, FPGA, protection systems | S7: Product development/firmware engineer | T7: Harder industrial path but real hardware.
A8: Chicago | B8: Littelfuse | C8: Chicago, IL | D8: Circuit protection / power control / sensors / semiconductors | E8: Produces fuses, relays, semiconductors, switches, sensors, and power/protection components. | F8: Good chip-adjacent target for power semiconductor, sensing, applications engineering, validation, and product engineering. | G8: 4 | H8: 3 | I8: =G8+H8 | J8: https://www.littelfuse.com/ | K8: https://www.littelfuse.com/company/careers | L8: https://www.littelfuse.com/products | M8: https://www.littelfuse.com/ | N8: Search semiconductors, sensors, power electronics, product/applications engineering; reach out around power/control interests. | O8: Not contacted | R8: power electronics, semiconductor, sensors, applications engineering, validation | S8: Applications/product engineer | T8: Closer to components than systems; still relevant.
A9: Chicago | B9: Argonne National Laboratory | C9: Lemont, IL | D9: National lab / quantum / microelectronics / advanced computing | E9: Argonne offers careers and undergraduate research opportunities in a cutting-edge research environment, including quantum information science. | F9: Strong if you want photonics/quantum/computing-adjacent research exposure and serious lab credibility. | G9: 4 | H9: 4 | I9: =G9+H9 | J9: https://www.anl.gov/ | K9: https://www.anl.gov/hr/careers | L9: https://www.anl.gov/education/undergraduate-internship-opportunities | M9: https://www.anl.gov/quantum/qis-opportunities | N9: Track undergraduate internships and temporary roles; message researchers after reading a specific project page. | O9: Not contacted | R9: quantum, microelectronics, photonics, computing, undergraduate internship, electronics | S9: Researcher, staff engineer, or internship coordinator | T9: Best as research/networking target.
A10: Chicago | B10: Fermilab | C10: Batavia, IL | D10: Particle physics lab / accelerator electronics / controls / instrumentation | E10: Fermilab builds and operates accelerator and detector facilities and has engineering, technology, computing, technical, and student programs. | F10: Good for electronics, controls, real-time systems, instrumentation, RF, scientific computing, and hardware-software integration. | G10: 4 | H10: 4 | I10: =G10+H10 | J10: https://www.fnal.gov/ | K10: https://jobs.fnal.gov/ | L10: https://jobs.fnal.gov/ | M10: https://news.fnal.gov/2025/07/fermilab-partners-with-community-colleges-to-develop-technical-talent/ | N10: Search student, electronics, controls, accelerator, detector, software, technician/engineering paths. | O10: Not contacted | P10: 46253 | R10: electronics, controls, instrumentation, RF, detector, accelerator, real-time systems | S10: Engineer or student-program contact | T10: Good bridge between ECE and physics. | U10: APPLIED FOR JR. ASIC ENGINEER ROLE
A11: Chicago | B11: Chamberlain Group | C11: Oak Brook / Elmhurst, IL | D11: Smart access / IoT / firmware / mobile + cloud | E11: Global intelligent access company powered by myQ with official careers page and local hybrid roles. | F11: Good product-company path for firmware, embedded, IoT devices, mobile/cloud integration, test, and product systems. | G11: 4 | H11: 4 | I11: =G11+H11 | J11: https://chamberlaingroup.com/ | K11: https://chamberlain.wd1.myworkdayjobs.com/Chamberlain_Group | L11: https://chamberlaingroup.com/careers | M11: https://chamberlaingroup.com/ | N11: Search firmware, hardware test, embedded, IoT, QA, mobile; mention interest in connected product systems. | O11: Not contacted | R11: firmware, embedded, IoT, hardware test, mobile, myQ | S11: Firmware or hardware test engineer | T11: Good if you want practical connected-products work.
A12: Chicago | B12: Panduit | C12: Tinley Park, IL | D12: Electrical/network infrastructure / industrial wiring / connectivity | E12: Develops network infrastructure and industrial electrical wiring solutions from the data center to the plant floor. | F12: Chip-adjacent rather than chip-core; useful for industrial infrastructure, fiber, physical network products, test, and product engineering. | G12: 3 | H12: 3 | I12: =G12+H12 | J12: https://www.panduit.com/ | K12: https://www.panduit.com/en/about/careers.html | L12: https://www.panduit.com/en/about/about-panduit.html | M12: https://www.panduit.com/en/about/media-resources/panduit-announces-key-executive-appointments.html | N12: Search product/electrical/test roles; message product engineers if you find fiber/connectivity overlap. | O12: no internships | P12: 46255 | R12: electrical, product engineer, fiber, network infrastructure, test | S12: Product/electrical engineer | T12: Secondary Chicago target.
A13: Chicago | B13: UL Solutions | C13: Northbrook, IL | D13: Electronics safety / EMC / wireless testing / certification | E13: Northbrook facility provides EMC and wireless testing for consumer and industrial electronics, medical devices, appliances, and lighting. | F13: Good entry point into test engineering, compliance, EMC, RF/wireless lab work, and product validation. | G13: 3 | H13: 4 | I13: =G13+H13 | J13: https://www.ul.com/ | K13: https://www.ul.com/careers | L13: https://www.ul.com/careers/internship | M13: https://www.ul.com/resources/northbrook-il-emc-and-wireless-laboratory | N13: Search Northbrook for lab engineer, EMC, wireless, electrical, certification, test; use it as validation/test pathway. | O13: Not contacted | R13: EMC, wireless, test engineer, electrical, compliance, validation | S13: Lab/test engineer or early-careers recruiter | T13: Not design-heavy but excellent test credential.
A14: Chicago | B14: mHUB | C14: Chicago, IL | D14: HardTech incubator / startup network / prototyping | E14: Chicago hardtech hub with prototyping labs, industry partnerships, and member-company career opportunities. | F14: Best ecosystem/networking target for finding small hardware startups before they post traditional roles. | G14: 3 | H14: 5 | I14: =G14+H14 | J14: https://mhub.org/ | K14: https://www.mhubchicago.com/careers/tag/member-company-career | L14: https://mhub.org/ | M14: https://www.mhubchicago.com/careers/tag/member-company-career | N14: Monitor member-company roles; attend events; ask who is building electronics, robotics, sensing, IoT, or energy hardware. | O14: Not contacted | R14: hardtech, electronics, robotics, sensing, IoT, prototyping, startup | S14: Member-company founder or program manager | T14: High-leverage networking board.
A15: Chicago | B15: Wabtec | C15: Buffalo Grove, IL | D15: Transportation systems / rail electronics / embedded software | E15: Wabtec has had Buffalo Grove embedded and manufacturing engineering roles; official careers page lists engineering/software/system roles. | F15: Worth tracking for embedded software, rail/transit systems, test, manufacturing engineering, and safety-critical product work. | G15: 3 | H15: 3 | I15: =G15+H15 | J15: https://www.wabteccorp.com/ | K15: https://careers.wabtec.com/ | L15: https://careers.wabtec.com/ | M15: https://www.wabteccorp.com/hiring | N15: Search Buffalo Grove for embedded/software/test/manufacturing engineer; secondary but real systems work. | O15: Not contacted | P15: 46253 | R15: embedded, manufacturing engineer, systems engineer, rail, test | S15: Engineering recruiter or product engineer | T15: Secondary Chicago-area systems target.
A16: Milwaukee | B16: Rockwell Automation | C16: Milwaukee / Mequon, WI | D16: Industrial automation / controls / hardware + software | E16: Global industrial automation and digital transformation company with careers and student programs; job board shows Milwaukee/Mequon hardware engineering signals. | F16: Probably the single strongest Milwaukee target for controls, embedded, hardware, firmware, industrial networks, and systems engineering. | G16: 5 | H16: 5 | I16: =G16+H16 | J16: https://www.rockwellautomation.com/en-us.html | K16: https://www.rockwellautomation.com/en-us/careers.html | L16: https://jobs.rockwellautomation.com/ | M16: https://www.rockwellautomation.com/en-gb/careers/edge-student-early-career/edge-student-programs.html | N16: Search hardware, firmware, controls, embedded, Mequon/Milwaukee; apply and message UW/MSOE-connected engineers. | O16: Not contacted | P16: 46272 | R16: hardware, firmware, controls, embedded, PLC, industrial automation, verification | S16: Hardware/controls engineer or campus recruiter | T16: Core Milwaukee target. | U16: SOFTWARE DEV INTERN APPLIED
A17: Milwaukee | B17: Milwaukee Tool | C17: Brookfield / Milwaukee, WI | D17: Power tools / embedded electronics / firmware / power electronics | E17: Electrical engineering roles explicitly include embedded systems, power electronics, motors, firmware, and system engineering; internships are mainly in Brookfield/Milwaukee. | F17: Elite practical fit for embedded C/C++, motor control, battery systems, power electronics, hardware/firmware integration, and fast product cycles. | G17: 5 | H17: 5 | I17: =G17+H17 | J17: https://www.milwaukeetool.com/ | K17: https://www.milwaukeetool.jobs/ | L17: https://www.milwaukeetool.jobs/career-areas/engineering/electrical-engineering | M17: https://www.milwaukeetool.jobs/GradsAndInterns/Internships | N17: Search firmware, embedded, motor control, electrical, battery, test automation; send project-focused outreach. | O17: Not contacted | P17: 46239 | R17: embedded C/C++, firmware, motor control, power electronics, battery, electrical, test automation | S17: Firmware/electrical engineer or early-careers recruiter | T17: Core Milwaukee target. No pertinent position on website.
A18: Milwaukee | B18: GE HealthCare | C18: Waukesha / West Milwaukee, WI | D18: Medical imaging / detectors / software + hardware systems | E18: GE HealthCare has engineering/technology and early-career funnels with Wisconsin imaging/manufacturing signals. | F18: Good systems employer for medical imaging, detector hardware, image processing, software, manufacturing engineering, and regulated product development. | G18: 4 | H18: 4 | I18: =G18+H18 | J18: https://www.gehealthcare.com/ | K18: https://careers.gehealthcare.com/ | L18: https://careers.gehealthcare.com/global/en/c/engineering-technology-jobs | M18: https://careers.gehealthcare.com/global/en/entry-level-opportunities | N18: Search Waukesha/West Milwaukee for engineering, imaging, detector, software, manufacturing, quality/test. | O18: Not contacted | P18: 46239 | R18: medical imaging, software, detector, manufacturing engineer, test, regulated systems | S18: Engineering recruiter or imaging systems engineer | T18: Strong if you want serious systems + software. No pertinent position on website.
A19: Milwaukee | B19: Leonardo DRS Naval Power Systems | C19: Menomonee Falls, WI | D19: Defense power systems / motor controls / automation / embedded | E19: Menomonee Falls site houses design, test, and manufacturing for naval power distribution, power conversion, motor controls, drives, and automation/control equipment. | F19: Strong fit for power electronics, embedded controls, C/C++, electrical engineering, test, and defense hardware. | G19: 4 | H19: 3 | I19: =G19+H19 | J19: https://www.leonardodrs.com/ | K19: https://careers.leonardodrs.com/ | L19: https://www.leonardodrs.com/locations/naval-power-systems-menomonee-falls-wi/ | M19: https://careers.leonardodrs.com/ | N19: Search Menomonee Falls for software engineer, electrical engineering tech, power conversion, controls; be aware of defense constraints. | O19: Not contacted | R19: embedded, C/C++, power conversion, motor controls, drives, automation, electrical | S19: Engineering recruiter or power systems engineer | T19: Serious hardware, less student-access friendly.
A20: Milwaukee | B20: Astronautics Corporation of America | C20: Oak Creek / Milwaukee, WI | D20: Avionics / aerospace electronics / mission systems | E20: Designs and manufactures avionics solutions including flight deck avionics, connectivity, cybersecurity, mission communications, and software development. | F20: Excellent path for embedded software, avionics, safety-critical systems, displays, cybersecurity, systems engineering, and verification. | G20: 4 | H20: 4 | I20: =G20+H20 | J20: https://www.astronautics.com/ | K20: https://www.astronautics.com/careers/ | L20: https://www.astronautics.com/careers/ | M20: https://www.astronautics.com/astronautics-achieving-hardware-milestone-for-its-connectivity-solution/ | N20: Search avionics software, systems, cybersecurity, electrical, verification; tailor around safety-critical systems. | O20: Not contacted | R20: avionics, embedded software, cybersecurity, systems, displays, verification | S20: Avionics/software engineer or recruiter | T20: High-quality Milwaukee-area aerospace target.
A21: Milwaukee | B21: Generac | C21: Reno, NV | D21: Power systems / embedded controls / firmware / energy tech | E21: Energy technology company with roles in firmware, controls, power electronics, product compliance, and co-op/intern programs. | F21: Very strong for embedded controls, firmware, power generation, power electronics, validation, and hardware/software integrated systems. | G21: 4 | H21: 4 | I21: =G21+H21 | J21: https://www.generac.com/ | K21: https://www.generac.com/about/careers/ | L21: https://careers.generac.com/en/jobs/jr13290/firmware-engineer-ii/ | M21: https://careers.generac.com/en/jobs/jr13037/staff-automation-and-validation-engineer/ | N21: Search Waukesha for firmware, controls, validation, power electronics, lab/test, co-op/intern; emphasize real-product interest. | O21: Not contacted | P21: 46259 | R21: firmware, embedded controls, power electronics, validation, lab test, C/C++ | S21: Firmware/controls engineer or early-careers recruiter | T21: Strong practical embedded target. | U21: rejected
A22: Milwaukee | B22: Johnson Controls | C22: Glendale / Milwaukee, WI | D22: Building automation / controls / software / industrial systems | E22: Careers include early-career tracks and roles around building automation systems, software, controls, and data-center engineering. | F22: Good fit for controls, BAS/BMS, industrial networking, software, embedded-adjacent systems, and customer-facing systems engineering. | G22: 3 | H22: 5 | I22: =G22+H22 | J22: https://www.johnsoncontrols.com/ | K22: https://jobs.johnsoncontrols.com/ | L22: https://jobs.johnsoncontrols.com/early-careers-north-america | M22: https://jobs.johnsoncontrols.com/job/WD30270943 | N22: Search Glendale/Milwaukee for controls, BAS, BMS, software, intern/co-op; do not ignore service/application paths. | O22: Not contacted | P22: 46240 | R22: controls, BAS, BMS, software, systems, automation, intern | S22: Controls/software engineer or early-careers recruiter | T22: Very accessible Milwaukee target. | U22: applied for data center software engineering role.
A23: Milwaukee | B23: Badger Meter | C23: Brown Deer / Milwaukee, WI | D23: Flow measurement / water quality / smart connected infrastructure / IoT | E23: Milwaukee-area manufacturer of flow measurement, water quality, and control products with IoT/network-connected infrastructure signals. | F23: Good embedded/IoT/product-systems path through sensors, connectivity, metering, field devices, manufacturing/test, and data-enabled hardware. | G23: 3 | H23: 4 | I23: =G23+H23 | J23: https://www.badgermeter.com/ | K23: https://www.badgermeter.com/company/careers | L23: https://www.badgermeter.com/ | M23: https://www.badgermeter.com/ | N23: Search careers for embedded, firmware, electrical, test, IoT, product engineering, manufacturing engineering. | O23: Not contacted | R23: embedded, IoT, sensors, metering, firmware, test, product engineer | S23: Electrical/product engineer | T23: Good under-the-radar Wisconsin hardware company.
A24: Milwaukee | B24: Komatsu | C24: Milwaukee, WI | D24: Mining equipment / autonomy / electric systems / industrial hardware | E24: Komatsu has a Milwaukee South Harbor presence and smart mining/autonomous equipment technology. | F24: Useful for autonomy, embedded/controls, industrial networking, power systems, heavy equipment, and engineering operations. | G24: 3 | H24: 3 | I24: =G24+H24 | J24: https://www.komatsu.com/en-us | K24: https://www.komatsu.com/en-us/careers | L24: https://www.komatsu.com/en-us/technology/smart-mining | M24: https://www.komatsu.com/en-us/newsroom/2023/komatsu-moves-into-new-south-harbor-home | N24: Search Milwaukee for electrical, controls, automation, software, product support, test, systems roles. | O24: Not contacted | P24: 46240 | R24: controls, autonomy, electrical, embedded, industrial networking, mining | S24: Controls/electrical engineer | T24: Strong industrial systems; not pure ECE but useful. | U24: applied to brazil internship kinda dum whateva.
A25: Milwaukee | B25: Brady Corporation | C25: Milwaukee, WI | D25: Identification / RFID / printers / industrial traceability | E25: Milwaukee company with products around industrial identification, traceability, printers, RFID scanners, and software. | F25: Good for RFID, scanners, printer hardware, firmware, embedded software, manufacturing systems, and industrial automation-adjacent work. | G25: 3 | H25: 4 | I25: =G25+H25 | J25: https://www.bradyid.com/ | K25: https://www.bradyid.com/corporate/careers | L25: https://www.bradyid.com/corporate/careers | M25: https://www.bradyid.com/intelligent-manufacturing/what-is-rfid | N25: Search RFID, firmware, printer, scanner, software, electrical, product/test engineering. | O25: Not contacted | R25: RFID, firmware, scanner, printer, software, electrical, product test | S25: Product/firmware engineer | T25: Worth a practical outreach shot.
